Workbook

Sheet Summary
A1: Department | C1: Budget Approval
C2: Capex-A(Asset) | E2: K(Cost center)-Opex (Service) | G2: Total Budget
A3: L1 | B3: L2 | C3: Monthly | D3: Recurring | E3: Monthly | F3: Recurring | G3: Capex-A(Asset) | H3: K(Cost center)-Opex (Service)
A4: Pilot Plant | B4: Operation | C4: =SUMIFS('Capex-A(Asset)'!$Q:$Q,'Capex-A(Asset)'!$D:$D,Summary!$B4,'Capex-A(Asset)'!$Z:$Z,C$3) -> 0 | D4: =SUMIFS('Capex-A(Asset)'!$Q:$Q,'Capex-A(Asset)'!$D:$D,Summary!$B4,'Capex-A(Asset)'!$Z:$Z,D$3) -> 0 | E4: =SUMIFS('K(Cost center)-Opex (Service)'!$O:$O,'K(Cost center)-Opex (Service)'!$D:$D,$B4,'K(Cost center)-Opex (Service)'!$X:$X,E$3) -> 7500 | F4: =SUMIFS('K(Cost center)-Opex (Service)'!$S:$S,'K(Cost center)-Opex (Service)'!$D:$D,$B4,'K(Cost center)-Opex (Service)'!$X:$X,F$3) -> 16413 | G4: =SUM(C4:D4) -> 0 | H4: =SUM(E4:F4) -> 23913
B5: Process Engineer | C5: =SUMIFS('Capex-A(Asset)'!$Q:$Q,'Capex-A(Asset)'!$D:$D,Summary!$B5,'Capex-A(Asset)'!$Z:$Z,C$3) -> 0 | D5: =SUMIFS('Capex-A(Asset)'!$Q:$Q,'Capex-A(Asset)'!$D:$D,Summary!$B5,'Capex-A(Asset)'!$Z:$Z,D$3) -> 0 | E5: =SUMIFS('K(Cost center)-Opex (Service)'!$S:$S,'K(Cost center)-Opex (Service)'!$D:$D,$B5,'K(Cost center)-Opex (Service)'!$X:$X,E$3) -> 0 | F5: =SUMIFS('K(Cost center)-Opex (Service)'!$S:$S,'K(Cost center)-Opex (Service)'!$D:$D,$B5,'K(Cost center)-Opex (Service)'!$X:$X,F$3) -> 1000 | G5: =SUM(C5:D5) -> 0 | H5: =SUM(E5:F5) -> 1000
B6: Process Management | C6: =SUMIFS('Capex-A(Asset)'!$Q:$Q,'Capex-A(Asset)'!$D:$D,Summary!$B6,'Capex-A(Asset)'!$Z:$Z,C$3) -> 0 | D6: =SUMIFS('Capex-A(Asset)'!$Q:$Q,'Capex-A(Asset)'!$D:$D,Summary!$B6,'Capex-A(Asset)'!$Z:$Z,D$3) -> 0 | E6: =SUMIFS('K(Cost center)-Opex (Service)'!$S:$S,'K(Cost center)-Opex (Service)'!$D:$D,$B6,'K(Cost center)-Opex (Service)'!$X:$X,E$3) -> 0 | F6: =SUMIFS('K(Cost center)-Opex (Service)'!$S:$S,'K(Cost center)-Opex (Service)'!$D:$D,$B6,'K(Cost center)-Opex (Service)'!$X:$X,F$3) -> 0 | G6: =SUM(C6:D6) -> 0 | H6: =SUM(E6:F6) -> 0
B7: Ware House | C7: =SUMIFS('Capex-A(Asset)'!$Q:$Q,'Capex-A(Asset)'!$D:$D,Summary!$B7,'Capex-A(Asset)'!$Z:$Z,C$3) -> 0 | D7: =SUMIFS('Capex-A(Asset)'!$Q:$Q,'Capex-A(Asset)'!$D:$D,Summary!$B7,'Capex-A(Asset)'!$Z:$Z,D$3) -> 0 | E7: =SUMIFS('K(Cost center)-Opex (Service)'!$S:$S,'K(Cost center)-Opex (Service)'!$D:$D,$B7,'K(Cost center)-Opex (Service)'!$X:$X,E$3) -> 0 | F7: =SUMIFS('K(Cost center)-Opex (Service)'!$S:$S,'K(Cost center)-Opex (Service)'!$D:$D,$B7,'K(Cost center)-Opex (Service)'!$X:$X,F$3) -> 1300 | G7: =SUM(C7:D7) -> 0 | H7: =SUM(E7:F7) -> 1300
B8: Process Safety | C8: =SUMIFS('Capex-A(Asset)'!$Q:$Q,'Capex-A(Asset)'!$D:$D,Summary!$B8,'Capex-A(Asset)'!$Z:$Z,C$3) -> 0 | D8: =SUMIFS('Capex-A(Asset)'!$Q:$Q,'Capex-A(Asset)'!$D:$D,Summary!$B8,'Capex-A(Asset)'!$Z:$Z,D$3) -> 0 | E8: =SUMIFS('K(Cost center)-Opex (Service)'!$S:$S,'K(Cost center)-Opex (Service)'!$D:$D,$B8,'K(Cost center)-Opex (Service)'!$X:$X,E$3) -> 0 | F8: =SUMIFS('K(Cost center)-Opex (Service)'!$S:$S,'K(Cost center)-Opex (Service)'!$D:$D,$B8,'K(Cost center)-Opex (Service)'!$X:$X,F$3) -> 0 | G8: =SUM(C8:D8) -> 0 | H8: =SUM(E8:F8) -> 0
B9: Maintenance | C9: =SUMIFS('Capex-A(Asset)'!$Q:$Q,'Capex-A(Asset)'!$D:$D,Summary!$B9,'Capex-A(Asset)'!$Z:$Z,C$3) -> 0 | D9: =SUMIFS('Capex-A(Asset)'!$Q:$Q,'Capex-A(Asset)'!$D:$D,Summary!$B9,'Capex-A(Asset)'!$Z:$Z,D$3) -> 0 | E9: =SUMIFS('K(Cost center)-Opex (Service)'!$O:$O,'K(Cost center)-Opex (Service)'!$D:$D,$B9,'K(Cost center)-Opex (Service)'!$X:$X,E$3) -> 32365.72 | F9: =SUMIFS('K(Cost center)-Opex (Service)'!$S:$S,'K(Cost center)-Opex (Service)'!$D:$D,$B9,'K(Cost center)-Opex (Service)'!$X:$X,F$3) -> 0 | G9: =SUM(C9:D9) -> 0 | H9: =SUM(E9:F9) -> 32365.72
B10: Process Control | C10: =SUMIFS('Capex-A(Asset)'!$Q:$Q,'Capex-A(Asset)'!$D:$D,Summary!$B10,'Capex-A(Asset)'!$Z:$Z,C$3) -> 0 | D10: =SUMIFS('Capex-A(Asset)'!$Q:$Q,'Capex-A(Asset)'!$D:$D,Summary!$B10,'Capex-A(Asset)'!$Z:$Z,D$3) -> 0 | E10: =SUMIFS('K(Cost center)-Opex (Service)'!$S:$S,'K(Cost center)-Opex (Service)'!$D:$D,$B10,'K(Cost center)-Opex (Service)'!$X:$X,E$3) -> 0 | F10: =SUMIFS('K(Cost center)-Opex (Service)'!$S:$S,'K(Cost center)-Opex (Service)'!$D:$D,$B10,'K(Cost center)-Opex (Service)'!$X:$X,F$3) -> 0 | G10: =SUM(C10:D10) -> 0 | H10: =SUM(E10:F10) -> 0
A11: Total | C11: =SUM(C4:C10) -> 0 | D11: =SUM(D4:D10) -> 0 | E11: =SUM(E4:E10) -> 39865.72 | F11: =SUM(F4:F10) -> 18713 | G11: =SUM(G4:G10) -> 0 | H11: =SUM(H4:H10) -> 58578.72

Sheet K(Cost center)-Opex (Service)
A1: Accounting Info. | H1: Requisition | O1: Budget Info. | Y1: Approve Info.
A2: No. | B2: Opex service | C2: Material No. /GL Account | D2: Cost Center | E2: PR Title | F2: Project | G2: Deliver to | H2: *Name | I2: *Description | J2: *UOM | K2: *Supplier Part Number | L2: *Need-by date | M2: *Comment/ Demand reason | N2: *Qty | O2: Unit price | P2: Freight | Q2: Net amount | R2: Taxes | S2: Total cost | T2: Currency | U2: Supplier | V2: Comment for price | W2: Inquired by Name/Date | X2: Type | Y2: Approved by | Z2: Approved date | AA2: Type of budget | AB2: Budget number
A3: Monthly Opex Service Budget (Need approval)
A4: 1 | C4: 6600370000 EA Exp-Maintenance fee | D4: Maintenance | E4: PP Equipment maintenance | H4: Repairs | I4: As yet unkonwn parts as a result of failure/need to replace | J4: EA | L4: 46142 | M4: As yet unkonwn parts as a result of failure/need to replace | N4: 1 | O4: 20000 | S4: 24000 | T4: GBP | U4: Various | V4: Monthly Call Off | X4: Monthly | AA4: Monthly | AB4: SW-NCH-M-202604-Maintenance
A5: 2 | C5: 6600370000 EA Exp-Maintenance fee | D5: Operation | E5: Building Fabric/Plumbing | H5: Building Fabric/Plumbing | I5: As yet unknown building fabric upkeep and repairs as a result of degredation/failure etc | J5: EA | L5: 46142 | M5: As yet unknown building fabric upkeep and repairs as a result of degredation/failure etc | N5: 1 | O5: 7500 | S5: 9000 | T5: GBP | U5: Shepway Commercial Services | V5: Monthly Call Off | X5: Monthly | AA5: Monthly | AB5: SW-NCH-M-202604-Operation
A6: 3 | C6: 6600370000 EA Exp-Maintenance fee | D6: Maintenance | E6: CMMS (HexagonEAM) technical support services | H6: CMMS Technical support services | I6: Call off for technical support to provide development and service support for CMMS system (HeaxagonEAM) to provide new reports, system enhancements etc. | J6: EA | L6: 46142 | M6: Call off for technical support to provide development and service support for CMMS system (HeaxagonEAM) to provide new reports, system enhancements etc. Provision of EAM from Hexagon does not come with enhancement/troubleshooting services for technical issues related to none infrastructure/access issues. We need to develop system reports further to respond to audit observations and streamline operation of system. | N6: 1 | O6: 5000 | S6: 6000 | T6: GBP | U6: Midport | V6: As per quote received based upon used hours in 2025/6 | X6: Monthly | AA6: Monthly | AB6: SW-NCH-M-202604-Maintenance
A7: 4 | C7: 6600370000 EA Exp-Maintenance fee | D7: Maintenance | E7: Reactor sample system 3 way valves | H7: Reactor system 3 way valves for conatined sample systems | I7: Replacement of failed reactor system 3 way valves for contained sample systems with new versions as supplied by DeDetriech. | J7: EA | L7: 46142 | M7: 2X sample system 3 way valves have failed in service and require replacing. Previous versions allowed for replacement of individual components, these are now obsolete and not available so a full valve assembly is required from OEM | O7: 7365.72 | S7: 8838.86 | T7: GBP | V7: Rubix | X7: Monthly | AA7: Monthly | AB7: SW-NCH-M-202604-Maintenance
A8: 5 | AA8: Monthly
A9: 6 | AA9: Monthly
A10: 7 | AA10: Monthly
A11: 8 | AA11: Monthly
A12: 9 | X12: Monthly | AA12: Monthly
X13: Monthly | AA13: Monthly
A14: Recurring Monthly Charges (For reviewing)
A15: 1 | B15: Repair and Maintainance contract/ad-hoc | C15: 6600370000 EA Exp-Maintenance fee | D15: Operation | H15: Housekeeping | I15: PP Headlock cleaning service via DPML | J15: EA | L15: 46081 | N15: 1 | O15: 4190 | S15: 4190 | T15: GBP | U15: Discovery Park/DPML | V15: Based on contract in place with DPML | X15: Recurring
A16: 2 | B16: DPML Sevice | C16: 6600280000 EA Expenses-testing charges | D16: Operation | H16: Service Charge | I16: PP Facility service charge | J16: EA | L16: 46081 | N16: 1 | O16: 11523 | S16: 11523 | T16: GBP | U16: Discovery Park/DPML | V16: Based on contract in place with DPML | X16: Recurring
A17: 3 | B17: Purified Water Testing | C17: 6600280000 EA Expenses-testing charges | D17: Operation | E17: Purified Water testing | H17: Purified Water testing | I17: Monthly water sampling/testing charges for PP | J17: EA | L17: 46081 | N17: 1 | O17: 700 | S17: 700 | T17: GBP | U17: Nalco | V17: Based on quote in progress with Nalco | X17: Recurring
A18: 4 | B18: =IFERROR(VLOOKUP(C18,reference!$D$9:$E$30,2,0),"") -> Logistics | C18: 6600240100 EA Exp-Transportation and storage costs | D18: Ware House | E18: Dawsons Api Store | H18: Provision of temperature controlled storage unit dedicated for API storage | I18: Monthly rental | J18: EA | L18: 46081 | M18: Dedicated controlled storage space required for completed APIs | N18: 1 | O18: 1300 | S18: =N18*O18+P18 -> 1300 | T18: GBP | U18: Dawsons | V18: As per contract (36 mth) agreed with Daswons | X18: Recurring
A19: 5 | C19: 6600420000 EA Expenses-consulting | D19: Process Engineer | H19: Draftsman routine updates | I19: PP controlled drawings require routine updates as and when changes are made for all changes (both CAPEX and none CAPEX) that impact the drawings. Monthly call off to ensure we can execute updates as and when they occur to ensure compliance for afety and quality. | J19: EA | L19: 46081 | M19: Previous order for controlled drawings updates will be fully consumed and there are a number of required items outstanding (. | N19: 1 | O19: 1000 | S19: 1000 | T19: GBP | U19: RB Plant | V19: Estimate for a routine monthly call off to ensure we can routinely update controlled drawings as and when they are required to be updated for safety and quality compliance | X19: Recurring

Sheet Capex-A(Asset)
A1: Accounting Info. | H1: Requisition | O1: Budget Info. | X1: Approve Info. | AB1: Order Info. in Ariba | AE1: Receipt Info. in Ariba
A2: No. | B2: Sort | C2: Material No. /GL Account | D2: Cost Center | E2: Asset Number (From Finace) | F2: Project | G2: Deliver to | H2: *Name | I2: *Description | J2: *UOM | K2: *Supplier Part Number | L2: *Need-by date | M2: *Comment/ Demand reason | N2: *Qty | O2: Unit price | P2: Freight | Q2: Net amount | R2: Taxes | S2: Total cost | T2: Currency | U2: Supplier | V2: Comment for price | W2: Inquired by Name/Date | X2: Approved by | Y2: Approved date | Z2: Type of budget | AA2: Budget number | AB2: PR No. | AC2: Ordered date | AD2: Comment for order | AE2: Qty | AF2: Received date
A3: 1 | C3: 6600800200 | Q3: =O3*N3+P3 -> 0 | R3: =Q3*0.2 -> 0 | S3: =R3+Q3 -> 0 | Z3: Monthly | AA3: ="SW-NCH-"&LEFT(Z3,1)&"-202410-"&E3 -> SW-NCH-M-202410-
A4: 2 | C4: 6600800200 | Q4: =O4*N4+P4 -> 0 | R4: =Q4*0.2 -> 0 | S4: =R4+Q4 -> 0
A5: 3 | C5: 6600800200 | Q5: =O5*N5+P5 -> 0 | R5: =Q5*0.2 -> 0 | S5: =R5+Q5 -> 0
A6: 4 | C6: 6600800200 | Q6: =O6*N6+P6 -> 0 | R6: =Q6*0.2 -> 0 | S6: =R6+Q6 -> 0
A7: 5 | C7: 6600800200 | Q7: =O7*N7+P7 -> 0 | R7: =Q7*0.2 -> 0 | S7: =R7+Q7 -> 0
A8: 6 | C8: 6600800200 | Q8: =O8*N8+P8 -> 0 | R8: =Q8*0.2 -> 0 | S8: =R8+Q8 -> 0
Q9: =O9*N9+P9 -> 0 | R9: =Q9*0.2 -> 0 | S9: =R9+Q9 -> 0
Q10: =O10*N10+P10 -> 0 | R10: =Q10*0.2 -> 0 | S10: =R10+Q10 -> 0
Q11: =O11*N11+P11 -> 0 | R11: =Q11*0.2 -> 0 | S11: =R11+Q11 -> 0
Q12: =O12*N12+P12 -> 0 | R12: =Q12*0.2 -> 0 | S12: =R12+Q12 -> 0
Q13: =O13*N13+P13 -> 0 | R13: =Q13*0.2 -> 0 | S13: =R13+Q13 -> 0
Q14: =O14*N14+P14 -> 0 | R14: =Q14*0.2 -> 0 | S14: =R14+Q14 -> 0
Q15: =O15*N15+P15 -> 0 | R15: =Q15*0.2 -> 0 | S15: =R15+Q15 -> 0
Q16: =O16*N16+P16 -> 0 | R16: =Q16*0.2 -> 0 | S16: =R16+Q16 -> 0
Q17: =O17*N17+P17 -> 0 | R17: =Q17*0.2 -> 0 | S17: =R17+Q17 -> 0
Q18: =O18*N18+P18 -> 0 | R18: =Q18*0.2 -> 0 | S18: =R18+Q18 -> 0
Q19: =O19*N19+P19 -> 0 | R19: =Q19*0.2 -> 0 | S19: =R19+Q19 -> 0
Q20: =O20*N20+P20 -> 0 | R20: =Q20*0.2 -> 0 | S20: =R20+Q20 -> 0
... Q165: =O165*N165+P165 -> 0 | R165: =Q165*0.2 -> 0 | S165: =R165+Q165 -> 0

Sheet reference
A1: Account Assignment | B1: Sort | C1: Budget No. | D1: Project/WBS | E1: Cost Center | F1: Asset Number | G1: GL Account | H1: Material No. | I1: Document Type of PO | L1: SAP Plant | M1: Material No. | N1: 物料描述 | O1: Description | P1: Department | R1: Department(L1) | S1: Department(L2) | U1: Project | X1: Sandwich budget coding rule
A2: P(Project) | B2: R&D Project | C2: N/A | D2: Detailed | E2: × | F2: × | G2: 5101010000 | H2: 5101010000 | I2: Z106 Expense PO | L2: SW1 | M2: 6600060100 | N2: 费用-办公费 | O2: Expenses-office allowance | P2: Administration & HR | R2: Pilot Plant | S2: Operation | U2: A0001
A3: D(Inventory material) | B3: Mfg Project | C3: Project Budget No. | D3: Detailed | E3: × | F3: × | G3: × | H3: Detailed | I3: Z108 Chemical PO | L3: SW1 | M3: 6600060200 | N3: 费用-通讯费用 | O3: Telephone fee | P3: IT | S3: Process Engineer | X3: 1.plant code | Y3: meaning | Z3: 2.material | AA3: full name | AB3: 3.budget type | AC3: full name | AD3: 4.month | AE3: full name | AF3: 5.department | AG3: 6.series number | AH3: budget number
A4: K(Cost center) | B4: Opex (Material) | C4: Opex Budget No. | D4: A0001 | E4: Detailed | F4: × | G4: 6600110000 | H4: 6600110000 | I4: Z106 Expense PO | L4: SW1 | M4: 6600060400 | N4: 费用-会议费-内部 | O4: Expense-Office maintenance | P4: BD | S4: Process Management | W4: sample1 | X4: SW | Y4: Sandwich | Z4: CH | AA4: Chemical | AB4: M | AC4: monthly budget | AD4: 202406 | AE4: June, 2024 | AF4: QC | AH4: SW-CH-M-202406-QC
B5: Opex (Service) | C5: Opex Budget No. | D5: A0001 | E5: Detailed | F5: × | G5: Start with 6 | H5: Start with 6 | I5: Z106 Expense PO | L5: SW1 | M5: 6600060500 | N5: 费用-会议费-外部 | O5: Expense-Office repair | P5: BD | S5: Ware House | W5: sample2 | X5: SW | Y5: Sandwich | Z5: CH | AA5: Chemical | AB5: Q | AC5: Quarterly budget | AD5: 202406 | AE5: June, 2024 | AF5: QC | AH5: SW-CH-Q-202406-QC
A6: A(Asset) | B6: Capex | C6: Capex Budget No. | D6: A0001 Detailed | E6: × | F6: Detailed | G6: × | H6: 6600800200 | I6: Z105 Fixed assets PO | L6: SW1 | M6: 6600070100 | N6: 费用-广告费 | O6: Expenses-advertising charge | P6: BD | S6: Process Safety | W6: sample 3 | X6: SW | Y6: Sandwich | Z6: CH | AA6: Chemical | AB6: E | AC6: extraordinary budget | AD6: 202406 | AE6: June, 2024 | AF6: ARD | AG6: 1 | AH6: SW-CH-E-202406-ARD-001
L7: SW1 | M7: 6600070300 | N7: 费用-参展费-国内 | O7: Expense- Exhibition fee - Domestic | P7: BD | S7: Maintenance | W7: sample 4 | X7: SW | Y7: Sandwich | Z7: NCH | AA7: Non-Chemical | AB7: E | AC7: extraordinary budget | AD7: 202406 | AE7: June, 2024 | AF7: ARD | AG7: 2 | AH7: SW-NCH-E-202406-ARD-002
L8: SW1 | M8: 6600070400 | N8: 费用-参展费-国外 | O8: Expense - Exhibition fees - Foreign | P8: BD | S8: Process Control
A9: Material No. | B9: Description | C9: Used for | D9: Drop-down options | E9: Opex service | G9: Mfg project | H9: R&D project | I9: Opex Material | J9: Capex | L9: SW1 | M9: 6600090100 | N9: 费用-车辆费用 | O9: Exp-Vehicle cost | P9: HR & Administration | R9: Lab | S9: ARD
A10: 6600800200 | B10: Construction in progress - equipment procurement | C10: Capital/software | D10: =A10&" EA "&B10 -> 6600800200 EA Construction in progress - equipment procurement | E10: Capex | G10: SM | H10: SM | I10: Consumables | J10: New equipment | L10: SW1 | M10: 6600100000 | N10: 费用-业务招待费 | O10: Expenses-business entertainment expense | P10: BD | S10: CRD | X10: CH/NCH | Y10: Type | Z10: Month | AA10: Dept | AB10: series Nr | AC10: budget number
A11: 6600060100 | B11: Expenses-office allowance | C11: stationery | D11: =A11&" EA "&B11 -> 6600060100 EA Expenses-office allowance | E11: Opex (Material) | G11: Regent | H11: Project specific reagent/solvent/salt | I11: Common reagent /solvent/salt | J11: Overhaul | L11: SW1 | M11: 6600170100 | N11: 费用-招聘费用 | O11: Expenses-recruitment expenses | P11: HR | S11: QC | X11: NCH | Y11: M | Z11: 202410 | AA11: Operation | AC11: =IF(Y11="M","SW-"&X11&"-"&Y11&"-"&Z11&"-"&AA11,"SW-"&X11&"-"&Y11&"-"&Z11&"-"&AA11&"-00"&AB11) -> SW-NCH-M-202410-Operation
A12: 6600110000 | B12: Expenses-meterial cost | C12: Opex consumables/regents | D12: =A12&" EA "&B12 -> 6600110000 EA Expenses-meterial cost | E12: Opex (Material) | G12: Bulk solvent | H12: Project specific column | I12: Common columns/parts | J12: Construction work project | L12: SW1 | M12: 6600170300 | N12: 费用-猎头费用 | O12: Exp-Headhunting fees | P12: HR | S12: API Technology and Engineering Sciences
A13: 5101010000 | B13: Project WBS received materials | C13: R&D Project materials | D13: =A13&" EA "&B13 -> 5101010000 EA Project WBS received materials | E13: R&D Project | G13: Inorganic salt | J13: Software | L13: SW1 | M13: 6600170400 | N13: 费用-培训费 | O13: Expenses-education and training | P13: HR | R13: EHS | S13: EHS
A14: 6600370000 | B14: Exp-Maintenance fee | C14: Maintenance | D14: =A14&" EA "&B14 -> 6600370000 EA Exp-Maintenance fee | E14: Repair and Maintainance contract/ad-hoc | G14: Regular chemical | I14: Opex service | L14: SW1 | M14: 6600170500 | N14: 费用-入职体检费 | O14: Expenses - Entry medical examination fee | P14: HR | R14: QA | S14: QA
A15: 6600170400 | B15: Expenses-education and training | C15: Training | D15: =A15&" EA "&B15 -> 6600170400 EA Expenses-education and training | E15: Training | G15: Consumables | I15: Facility/Waste | L15: SW1 | M15: 6600170600 | N15: 费用-入职交通费 | O15: Expenses - Entry transportation | P15: HR | R15: HR & Administration | S15: HR & Administration
A16: 6600280000 | B16: Expenses-testing charges | C16: Testing | D16: =A16&" EA "&B16 -> 6600280000 EA Expenses-testing charges | E16: Calibration | G16: Column | I16: Repair and Maintainance contract/ad-hoc | L16: SW1 | M16: 6600180200 | N16: 费用-劳务费-其他 | O16: Expenses-labor wage | P16: HR | R16: Procurement | S16: Procurement
A17: 6600240100 | B17: Exp-Transportation and storage costs | C17: Separate Shipping | D17: =A17&" EA "&B17 -> 6600240100 EA Exp-Transportation and storage costs | E17: Logistics | G17: Special testing | I17: Logistics | L17: SW1 | M17: 6600190100 | N17: 费用-注册认证费 | O17: Exp-Registration certification fee | P17: RA | R17: Operation Management Office | S17: Operation Management Office
A18: 6600410000 | B18: Exp-Commissioned development | C18: R&D | D18: =A18&" EA "&B18 -> 6600410000 EA Exp-Commissioned development | G18: Special equipment | I18: Calibration | L18: SW1 | M18: 6600200100 | N18: 费用-药品注册费 | O18: Exp-Drug registration fees | P18: RA | R18: IT | S18: IT
A19: 6600420000 | B19: Expenses-consulting | D19: =A19&" EA "&B19 -> 6600420000 EA Expenses-consulting | L19: SW1 | M19: 6600210100 | N19: 费用-中介服务费-咨询费 | O19: Expenses-consulting | P19: HR & Administration | R19: Finance | S19: Finance
A20: 5101010000 | B20: Project WBS received materials | D20: =A20&" EA "&B20 -> 5101010000 EA Project WBS received materials | L20: SW1 | M20: 6600210200 | N20: 费用-中介服务费-审计费 | O20: Expenses-auditing | P20: Finance
A21: 6600110000 | B21: Expenses-meterial cost | D21: =A21&" EA "&B21 -> 6600110000 EA Expenses-meterial cost | L21: SW1 | M21: 6600210300 | N21: 费用-中介服务费-律师费 | O21: Expenses-lawer | P21: HR & Administration
A22: 6600120000 | B22: Sample cost | D22: =A22&" EA "&B22 -> 6600120000 EA Sample cost | L22: SW1 | M22: 6600220000 | N22: 费用-保险费 | O22: Expenses-insurance | P22: Finance
A23: 6600350100 | B23: Exp-EHS cost - Metering and testing fee | C23: EHS | D23: =A23&" EA "&B23 -> 6600350100 EA Exp-EHS cost - Metering and testing fee | E23: Calibration | L23: SW1 | M23: 6600230100 | N23: 费用-能源-水费 | O23: Expenses-energy | P23: PP
A24: 6600350200 | B24: Expenses -EHS cost - Maintenance fees | D24: =A24&" EA "&B24 -> 6600350200 EA Expenses -EHS cost - Maintenance fees | E24: Repair and Maintainance contract/ad-hoc | L24: SW1 | M24: 6600230200 | N24: 费用-能源-电费 | O24: Exp-energy-Electricity | P24: PP
A25: 6600350300 | B25: Expenses-EHS cost-three wastes transportation cost | D25: =A25&" EA "&B25 -> 6600350300 EA Expenses-EHS cost-three wastes transportation cost | E25: Facility/Waste | L25: SW1 | M25: 6600230300 | N25: 费用-能源-蒸汽费 | O25: Exp-energy-steam | P25: PP
A26: 6600350400 | B26: Expenses -EHS cost - Three waste treatment fee | D26: =A26&" EA "&B26 -> 6600350400 EA Expenses -EHS cost - Three waste treatment fee | E26: Facility/Waste | L26: SW1 | M26: 6600230400 | N26: 费用-能源-天然气 | O26: Exp-energy-gas | P26: PP
A27: 6600350500 | B27: Expenses -EHS cost - Garbage removal fees | D27: =A27&" EA "&B27 -> 6600350500 EA Expenses -EHS cost - Garbage removal fees | E27: Facility/Waste | L27: SW1 | M27: 6600230500 | N27: 费用-能源-采暖费 | O27: Exp-energy-heating | P27: PP
A28: 6600350600 | B28: Expenses -EHS cost - Training fees | D28: =A28&" EA "&B28 -> 6600350600 EA Expenses -EHS cost - Training fees | E28: Training | L28: SW1 | M28: 6600230600 | N28: 费用-能源-柴油 | O28: Exp-energy-diesel | P28: PP
A29: 6600350700 | B29: Expenses -EHS cost - Property fees | D29: =A29&" EA "&B29 -> 6600350700 EA Expenses -EHS cost - Property fees | E29: Facility/Waste | L29: SW1 | M29: 6600230700 | N29: 费用-能源-煤 | O29: Exp-energy-coal | P29: PP
A30: 6600350800 | B30: Expenses -EHS cost - Evaluation fees | D30: =A30&" EA "&B30 -> 6600350800 EA Expenses -EHS cost - Evaluation fees | E30: Facility/Waste | L30: SW1 | M30: 6600240200 | N30: 费用-运输-出口费用 | O30: Exp-transport costs | P30: HR & Administration
A31: 6600350900 | B31: Expenses -EHS cost - Monitoring fees | D31: =A31&" EA "&B31 -> 6600350900 EA Expenses -EHS cost - Monitoring fees | E31: Facility/Waste | L31: SW1 | M31: 6600250000 | N31: 费用-进口代理费 | O31: Exp-ImportAgencyFees | P31: HR & Administration
A32: 6600351000 | B32: Expenses -EHS cost - Health fees | D32: =A32&" EA "&B32 -> 6600351000 EA Expenses -EHS cost - Health fees | E32: Facility/Waste | L32: SW1 | M32: 6600260000 | N32: 费用-关税 | O32: Expenses-tariff | P32: HR & Administration
A33: 6600351100 | B33: Expenses -EHS cost - Security fees | D33: =A33&" EA "&B33 -> 6600351100 EA Expenses -EHS cost - Security fees | E33: Facility/Waste | L33: SW1 | M33: 6600270000 | N33: 费用-加工费 | O33: Expenses-processing charges | P33: PP
A34: 6600351200 | B34: Expenses -EHS cost - Other | D34: =A34&" EA "&B34 -> 6600351200 EA Expenses -EHS cost - Other | E34: Facility/Waste | L34: SW1 | M34: 6600280000 | N34: 费用-检测费用 | O34: Expenses-testing charges | P34: QA&QC
L35: SW1 | M35: 6600290000 | N35: 费用-专利费 | O35: Expenses-patent charges | P35: HR & Administration
L36: SW1 | M36: 6600300000 | N36: 费用-协会会费 | O36: Exp-Association dues | P36: HR & Administration
L37: SW1 | M37: 6600340100 | N37: 费用-行政物业费 | O37: Exp-Administrative property fees | P37: Administration
L38: SW1 | M38: 6600340200 | N38: 费用-保洁费 | O38: Exp-Cleaning fee | P38: Administration
L39: SW1 | M39: 6600350100 | N39: 费用-EHS费用-计量检测费 | O39: Exp-EHS cost - Metering and testing fee | P39: EHS
L40: SW1 | M40: 6600350200 | N40: 费用-EHS费用-维修维护费 | O40: Expenses -EHS cost - Maintenance fees | P40: EHS
...
